Workbook
Name Amount: #REF!
Name Creator: #REF!
Name CUR: #REF!
Name cv: #REF!
Name D: #REF!
Name df: #REF!
Name DF_GRID_1: #REF!
Name DF_NAVPANEL_13: #REF!
Name DF_NAVPANEL_18: #REF!
Name Display_Week: #REF!
Name Doc: #REF!
Name DP: #REF!
Name FinancialYear: #REF!
Name FLAG: #REF!
Name Label_Main3: OFFSET(#REF!,0,0,#REF!,1),#REF!,OFFSET(#REF!,0,0,#REF!,1),#REF!,OFFSET(#REF!,0,0,#REF!,1),#REF!
Name Label_Nv3: OFFSET(#REF!,0,0,#REF!,1),#REF!,OFFSET(#REF!,0,0,#REF!,1),#REF!,OFFSET(#REF!,0,0,#REF!,1),#REF!
Name LastMonth: #REF!
Name MasterFormula: #REF!
Name Names3: OFFSET(#REF!,0,0,#REF!,1),#REF!,OFFSET(#REF!,0,0,#REF!,1),#REF!,OFFSET(#REF!,0,0,#REF!,1),#REF!
Name Names4: #REF!,#REF!,#REF!,#REF!
Name P_Select: #REF!
Name Page1formula: #REF!
Name Page2formula: #REF!
Name Page3formula: #REF!
Name PROJECT: #REF!
Name Project_Start: #REF!
Name Region: #REF!
Name sanctioned: #REF!:#REF!
Name Slicer_DeliveryTheme: #N/A
Name Slicer_FundingPositionT3Proposed: #N/A
Name Slicer_In_Copperleaf?: #N/A
Name Slicer_PCD: #N/A
Name StartMonth: #REF!
Name Submitted: #REF!
Name TableName: "Dummy"
Name v: {"Japan_Capers_Ed_Pub",#N/A,FALSE,"DI 2 YEAR MASTER SCHEDULE"}
Name Val_Main3: OFFSET(#REF!,0,0,#REF!,1),#REF!,OFFSET(#REF!,0,0,#REF!,1),#REF!,OFFSET(#REF!,0,0,#REF!,1),#REF!
Name Val_Main4: OFFSET(#REF!,0,0,#REF!,1),#REF!,OFFSET(#REF!,0,0,#REF!,1),#REF!,OFFSET(#REF!,0,0,#REF!,1),#REF!
Name Val_Nv3: OFFSET(#REF!,0,0,#REF!,1),#REF!,OFFSET(#REF!,0,0,#REF!,1),#REF!,OFFSET(#REF!,0,0,#REF!,1),#REF!
Name Val_Nv4: OFFSET(#REF!,0,0,#REF!,1),#REF!,OFFSET(#REF!,0,0,#REF!,1),#REF!,OFFSET(#REF!,0,0,#REF!,1),#REF!
Name Val_Pv3: OFFSET(#REF!,0,0,#REF!,1),#REF!,OFFSET(#REF!,0,0,#REF!,1),#REF!,OFFSET(#REF!,0,0,#REF!,1),#REF!
Name Val_Pv4: OFFSET(#REF!,0,0,#REF!,1),#REF!,OFFSET(#REF!,0,0,#REF!,1),#REF!,OFFSET(#REF!,0,0,#REF!,1),#REF!
Name Val_Transparent3: OFFSET(#REF!,0,0,#REF!,1),#REF!,OFFSET(#REF!,0,0,#REF!,1),#REF!,OFFSET(#REF!,0,0,#REF!,1),#REF!
Name Val_Transparent4: OFFSET(#REF!,0,0,#REF!,1),#REF!,OFFSET(#REF!,0,0,#REF!,1),#REF!,OFFSET(#REF!,0,0,#REF!,1),#REF!
Name VALUE: #REF!
Name Vimbai_Chengeta: #REF!
Name Width_ETO: #REF!

Sheet SAP Data
B2: YTD TOTAL | C2: In Copperleaf? | D2: . | E2: Company Code | F2: Project Definition | G2: Project Definition | H2: WBS Element | I2: WBS Element | J2: Object Class | K2: Person Responsible | L2: Initiative ID | M2: Scheme No/Proj Ref | N2: WBS Regulatory Activity | O2: WBS Regulatory Activity | Posting period | P2: 1 | Q2: 2 | R2: 3 | S2: 4 | T2: 5 | U2: 6 | V2: 7 | W2: 8 | X2: 9 | Y2: 1PROJECT 0001 | Z2: 11 | AA2: 12
B3: 0 | C3: =IF(COUNTIF('Copperleaf Data'!O:O,'SAP Data'!F3)>0,"_Yes","No - "&LEFT(F3,3)) -> _Yes | E3: COMPANY 001 | F3: PROJECT 0280 | G3: PROJECT 1577 | H3: PROJECT PROJECT 000128PROJECT 0001-PROJECT 00011 | I3: Project Management | J3: IV | K3: PERSON 095 | L3: INITIATIVE 00010 | M3: INITIATIVE 01835 | N3: W99 | O3: 6.2 Projects - Dummy - W99 | P3: 4579.7542 | Q3: -4579.7542 | R3: 0 | S3: 0
B4: 77127.05 | C4: =IF(COUNTIF('Copperleaf Data'!O:O,'SAP Data'!F4)>0,"_Yes","No - "&LEFT(F4,3)) -> _Yes | E4: COMPANY 001 | F4: PROJECT 0280 | G4: PROJECT 1577 | H4: PROJECT PROJECT 000128PROJECT 0001-PROJECT 00011-PROJECT 00011-PROJECT 00012 | I4: GT Operations | J4: IV | K4: PERSON 095 | L4: INITIATIVE 00010 | M4: INITIATIVE 01835 | N4: W99 | O4: 6.2 Projects - Dummy - W99 | P4: 12091.767 | Q4: 14791.835 | R4: 13880.261 | S4: 15669.999
B5: 512918.02 | C5: =IF(COUNTIF('Copperleaf Data'!O:O,'SAP Data'!F5)>0,"_Yes","No - "&LEFT(F5,3)) -> _Yes | E5: COMPANY 001 | F5: PROJECT 0280 | G5: PROJECT 1577 | H5: PROJECT PROJECT 000128PROJECT 0001-PROJECT 00011-PROJECT 00011-PROJECT 00013 | I5: NG Overhead | J5: IV | K5: PERSON 095 | L5: INITIATIVE 00010 | M5: INITIATIVE 01835 | N5: W99 | O5: 6.2 Projects - Dummy - W99 | P5: 200175.19 | Q5: 84586.576 | R5: 85841.705 | S5: 4698.6481
B6: 822587.9 | C6: =IF(COUNTIF('Copperleaf Data'!O:O,'SAP Data'!F6)>0,"_Yes","No - "&LEFT(F6,3)) -> _Yes | E6: COMPANY 001 | F6: PROJECT 0280 | G6: PROJECT 1577 | H6: PROJECT PROJECT 000128PROJECT 0001-PROJECT 00011-PROJECT 00011-PROJECT 00014 | I6: Delivery Unit Project Management | J6: IV | K6: PERSON 095 | L6: INITIATIVE 00010 | M6: INITIATIVE 01835 | N6: W99 | O6: 6.2 Projects - Dummy - W99 | P6: 142161.5 | Q6: 158698.68 | R6: 116929.54 | S6: 184097.84
B7: 598.62 | C7: =IF(COUNTIF('Copperleaf Data'!O:O,'SAP Data'!F7)>0,"_Yes","No - "&LEFT(F7,3)) -> _Yes | E7: COMPANY 001 | F7: PROJECT 0280 | G7: PROJECT 1577 | H7: PROJECT PROJECT 000128PROJECT 0001-PROJECT 00012-PROJECT 00011-PROJECT 00013 | I7: External Affiars | J7: IV | K7: PERSON 095 | L7: INITIATIVE 00010 | M7: INITIATIVE 01835 | N7: W99 | O7: 6.2 Projects - Dummy - W99 | P7: 0 | Q7: 0 | R7: 0 | S7: 438.01025
B8: 49000 | C8: =IF(COUNTIF('Copperleaf Data'!O:O,'SAP Data'!F8)>0,"_Yes","No - "&LEFT(F8,3)) -> _Yes | E8: COMPANY 001 | F8: PROJECT 0280 | G8: PROJECT 1577 | H8: PROJECT PROJECT 000128PROJECT 0001-PROJECT 00012-PROJECT 00012-PROJECT 00013 | I8: Mechanical | J8: IV | K8: PERSON 095 | L8: INITIATIVE 00010 | M8: INITIATIVE 01835 | N8: W99 | O8: 6.2 Projects - Dummy - W99 | P8: 0 | Q8: 0 | R8: 19755.9 | S8: 16097.4
B9: -4082340 | C9: =IF(COUNTIF('Copperleaf Data'!O:O,'SAP Data'!F9)>0,"_Yes","No - "&LEFT(F9,3)) -> _Yes | E9: COMPANY 001 | F9: PROJECT 0280 | G9: PROJECT 1577 | H9: PROJECT PROJECT 000128PROJECT 0001-PROJECT 00012-PROJECT 00013-PROJECT 00011 | I9: Contractor Project Management | J9: IV | K9: PERSON 095 | L9: INITIATIVE 00010 | M9: INITIATIVE 01835 | N9: W99 | O9: 6.2 Projects - Dummy - W99 | P9: 2279119.3 | Q9: 1842098.3 | R9: -11306863 | S9: 4198597.5
B10: 52897.09 | C10: =IF(COUNTIF('Copperleaf Data'!O:O,'SAP Data'!F10)>0,"_Yes","No - "&LEFT(F10,3)) -> _Yes | E10: COMPANY 001 | F10: PROJECT 0280 | G10: PROJECT 1577 | H10: PROJECT PROJECT 000128PROJECT 0001-PROJECT 00012-PROJECT 00013-PROJECT 00016 | I10: All | J10: IV | K10: PERSON 095 | L10: INITIATIVE 00010 | M10: INITIATIVE 01835 | N10: W99 | O10: 6.2 Projects - Dummy - W99 | P10: 8048.7 | Q10: 1463.4 | R10: 24490.123 | S10: 4702.5774
B11: 4111458.6 | C11: =IF(COUNTIF('Copperleaf Data'!O:O,'SAP Data'!F11)>0,"_Yes","No - "&LEFT(F11,3)) -> _Yes | E11: COMPANY 001 | F11: PROJECT 0280 | G11: PROJECT 1577 | H11: PROJECT PROJECT 000128PROJECT 0001-PROJECT 00012-PROJECT 00014-PROJECT 00016 | I11: All | J11: IV | K11: PERSON 095 | L11: INITIATIVE 00010 | M11: INITIATIVE 01835 | N11: W99 | O11: 6.2 Projects - Dummy - W99 | P11: 0 | Q11: 0 | R11: 3008354.3 | S11: 0
B12: 1071733.5 | C12: =IF(COUNTIF('Copperleaf Data'!O:O,'SAP Data'!F12)>0,"_Yes","No - "&LEFT(F12,3)) -> _Yes | E12: COMPANY 001 | F12: PROJECT 0280 | G12: PROJECT 1577 | H12: PROJECT PROJECT 000128PROJECT 0001-PROJECT 00013-PROJECT 00011-PROJECT 00012 | I12: Accomodation & Facilities | J12: IV | K12: PERSON 095 | L12: INITIATIVE 00010 | M12: INITIATIVE 01835 | N12: W99 | O12: 6.2 Projects - Dummy - W99 | P12: 732.76828 | Q12: 593.7526 | R12: 781656.11 | S12: 1204.7733
B13: -12094 | C13: =IF(COUNTIF('Copperleaf Data'!O:O,'SAP Data'!F13)>0,"_Yes","No - "&LEFT(F13,3)) -> _Yes | E13: COMPANY 001 | F13: PROJECT 0280 | G13: PROJECT 1577 | H13: PROJECT PROJECT 000128PROJECT 0001-PROJECT 00013-PROJECT 00011-PROJECT 00013 | I13: Environmental Assessment | J13: IV | K13: PERSON 095 | L13: INITIATIVE 00010 | M13: INITIATIVE 01835 | N13: W99 | O13: 6.2 Projects - Dummy - W99 | P13: 0 | Q13: -8849.1798 | R13: 0 | S13: 0
B14: 6325495 | C14: =IF(COUNTIF('Copperleaf Data'!O:O,'SAP Data'!F14)>0,"_Yes","No - "&LEFT(F14,3)) -> _Yes | E14: COMPANY 001 | F14: PROJECT 0280 | G14: PROJECT 1577 | H14: PROJECT PROJECT 000128PROJECT 0001-PROJECT 00014-PROJECT 00012-PROJECT 00014 | I14: Rotating | J14: IV | K14: PERSON 095 | L14: INITIATIVE 00010 | M14: INITIATIVE 01835 | N14: W99 | O14: 6.2 Projects - Dummy - W99 | P14: 557319.06 | Q14: 1277045.5 | R14: 1277045.5 | S14: 1516954.6
... B57: 977.63 | C57: =IF(COUNTIF('Copperleaf Data'!O:O,'SAP Data'!F57)>0,"_Yes","No - "&LEFT(F57,3)) -> _Yes | E57: COMPANY 001 | F57: PROJECT 0462 | G57: PROJECT 1698 | H57: PROJECT PROJECT 0001462-PROJECT 00011-PROJECT 00011-PROJECT 00012 | I57: GT Operations | J57: IV | K57: PERSON 129 | L57: INITIATIVE 00173 | M57: INITIATIVE 02017 | N57: NBM | O57: IED-MCP-Baseline | P57: 486.42684 | Q57: 0 | R57: 114.45251 | S57: 114.45251
B58: =SUM(P58:AA58) -> 6329.7245 | C58: =IF(COUNTIF('Copperleaf Data'!O:O,'SAP Data'!F58)>0,"_Yes","No - "&LEFT(F58,3)) -> _Yes | E58: COMPANY 001 | F58: PROJECT 0462 | G58: PROJECT 1698 | H58: PROJECT PROJECT 0001462-PROJECT 00011-PROJECT 00011-PROJECT 00013 | I58: NG Overheads | J58: IV | K58: PERSON 129 | L58: INITIATIVE 00173 | M58: INITIATIVE 02017 | N58: NBM | O58: IED-MCP-Baseline | P58: 0 | Q58: 0 | R58: 603.6525 | S58: 5726.072
B59: =SUM(P59:AA59) -> -7470.6716 | C59: =IF(COUNTIF('Copperleaf Data'!O:O,'SAP Data'!F59)>0,"_Yes","No - "&LEFT(F59,3)) -> _Yes | E59: COMPANY 001 | F59: PROJECT 0462 | G59: PROJECT 1698 | H59: PROJECT PROJECT 0001462-PROJECT 00011-PROJECT 00011-PROJECT 00014 | I59: Delivery Unit Project Management | J59: IV | K59: PERSON 129 | L59: INITIATIVE 00173 | M59: INITIATIVE 02017 | N59: NBM | O59: IED-MCP-Baseline | P59: -6960.4865 | Q59: -723.16838 | R59: 212.98324 | S59: 0
B60: =SUM(P60:AA60) -> 4139.7464 | C60: =IF(COUNTIF('Copperleaf Data'!O:O,'SAP Data'!F60)>0,"_Yes","No - "&LEFT(F60,3)) -> _Yes | E60: COMPANY 001 | F60: PROJECT 0462 | G60: PROJECT 1698 | H60: PROJECT PROJECT 0001462-PROJECT 00011-PROJECT 00011-PROJECT 00016 | I60: GT System Operator | J60: IV | K60: PERSON 129 | L60: INITIATIVE 00173 | M60: INITIATIVE 02017 | N60: NBM | O60: IED-MCP-Baseline | P60: 581.60638 | Q60: 514.09974 | R60: 3044.0403 | S60: 0
B61: =SUM(P61:AA61) -> 99530.868 | C61: =IF(COUNTIF('Copperleaf Data'!O:O,'SAP Data'!F61)>0,"_Yes","No - "&LEFT(F61,3)) -> _Yes | E61: COMPANY 001 | F61: PROJECT 0462 | G61: PROJECT 1698 | H61: PROJECT PROJECT 0001462-PROJECT 00012-PROJECT 00012-PROJECT 00013 | I61: Mechanical | J61: IV | K61: PERSON 129 | L61: INITIATIVE 00173 | M61: INITIATIVE 02017 | N61: NBM | O61: IED-MCP-Baseline | P61: 0 | Q61: 0 | R61: 35622.134 | S61: 63908.734
B62: 23100.3 | C62: =IF(COUNTIF('Copperleaf Data'!O:O,'SAP Data'!F62)>0,"_Yes","No - "&LEFT(F62,3)) -> _Yes | E62: COMPANY 001 | F62: PROJECT 0694 | G62: PROJECT 1659 | H62: PROJECT PROJECT 0001694-PROJECT 00011-PROJECT 00011-PROJECT 00012 | I62: GT Operations | J62: IV | K62: PERSON 158 | L62: INITIATIVE 00158 | M62: TEMPLATE | N62: AAA | O62: Asset Health (Baseline) GT1 Carry Over | P62: 0 | Q62: 0 | R62: 0 | S62: 16902.49
B63: 13253.42 | C63: =IF(COUNTIF('Copperleaf Data'!O:O,'SAP Data'!F63)>0,"_Yes","No - "&LEFT(F63,3)) -> _Yes | E63: COMPANY 001 | F63: PROJECT 0915 | G63: PROJECT 1514 | H63: PROJECT PROJECT 0001915-PROJECT 00011-PROJECT 00011-PROJECT 00011 | I63: 4.PROJECT 00011 NGT Project Management | J63: IV | K63: PERSON 008 | L63: INITIATIVE 00192 | M63: TEMPLATE | N63: AAA | O63: Asset Health (Baseline) GT1 Carry Over | P63: 0 | Q63: 2651.293 | R63: 3314.1181 | S63: 3732.1163
B64: 17534.01 | C64: =IF(COUNTIF('Copperleaf Data'!O:O,'SAP Data'!F64)>0,"_Yes","No - "&LEFT(F64,3)) -> _Yes | E64: COMPANY 001 | F64: PROJECT 0915 | G64: PROJECT 1514 | H64: PROJECT PROJECT 0001915-PROJECT 00011-PROJECT 00011-PROJECT 00012 | I64: 4.PROJECT 00012 NGT Staff | J64: IV | K64: PERSON 008 | L64: INITIATIVE 00192 | M64: TEMPLATE | N64: AAA | O64: Asset Health (Baseline) GT1 Carry Over | P64: 0 | Q64: 0 | R64: 10665.991 | S64: 2163.6442
B65: 0 | C65: =IF(COUNTIF('Copperleaf Data'!O:O,'SAP Data'!F65)>0,"_Yes","No - "&LEFT(F65,3)) -> _Yes | E65: COMPANY 001 | F65: PROJECT 0915 | G65: PROJECT 1514 | H65: PROJECT PROJECT 0001915-PROJECT 00011-PROJECT 00011-PROJECT 00014 | I65: 4.PROJECT 00014 Overhead | J65: IV | K65: PERSON 008 | L65: INITIATIVE 00192 | M65: TEMPLATE | N65: AAA | O65: Asset Health (Baseline) GT1 Carry Over | P65: 0 | Q65: 0 | R65: 11920.878 | S65: -11920.878
B66: 2181.22 | C66: =IF(COUNTIF('Copperleaf Data'!O:O,'SAP Data'!F66)>0,"_Yes","No - "&LEFT(F66,3)) -> _Yes | E66: COMPANY 001 | F66: PROJECT 0915 | G66: PROJECT 1514 | H66: PROJECT PROJECT 0001915-PROJECT 00012-PROJECT 00014-PROJECT 00012 | I66: 4.14 NGT Staff | J66: IV | K66: PERSON 008 | L66: INITIATIVE 00192 | M66: TEMPLATE | N66: AAA | O66: Asset Health (Baseline) GT1 Carry Over | P66: 0 | Q66: 0 | R66: 298.57018 | S66: 1297.4285
B67: 80000 | C67: =IF(COUNTIF('Copperleaf Data'!O:O,'SAP Data'!F67)>0,"_Yes","No - "&LEFT(F67,3)) -> _Yes | E67: COMPANY 001 | F67: PROJECT 0915 | G67: PROJECT 1514 | H67: PROJECT PROJECT 0001915-PROJECT 00014-PROJECT 00012-PROJECT 00011 | I67: 4.24 Valves | J67: IV | K67: PERSON 008 | L67: INITIATIVE 00192 | M67: TEMPLATE | N67: AAA | O67: Asset Health (Baseline) GT1 Carry Over | P67: 0 | Q67: 0 | R67: 0 | S67: 58536
B68: 2216.61 | C68: =IF(COUNTIF('Copperleaf Data'!O:O,'SAP Data'!F68)>0,"_Yes","No - "&LEFT(F68,3)) -> _Yes | E68: COMPANY 001 | F68: PROJECT 0915 | G68: PROJECT 1514 | H68: PROJECT PROJECT 0001915-PROJECT 00017-PROJECT 00011-PROJECT 00011 | I68: 4.38 MWC Project Management | J68: IV | K68: PERSON 008 | L68: INITIATIVE 00192 | M68: TEMPLATE | N68: AAA | O68: Asset Health (Baseline) GT1 Carry Over | P68: 0 | Q68: 0 | R68: 0 | S68: 1621.8935
B69: 458.01 | C69: =IF(COUNTIF('Copperleaf Data'!O:O,'SAP Data'!F69)>0,"_Yes","No - "&LEFT(F69,3)) -> _Yes | E69: COMPANY 001 | F69: PROJECT 1107 | G69: PROJECT 1975 | H69: PROJECT 11PROJECT 00017-PROJECT 00011-PROJECT 00011-PROJECT 00014 | I69: 4.PROJECT 00014 Overhead | J69: IV | K69: PERSON 055 | L69: INITIATIVE 00282 | M69: INITIATIVE 02196 | N69: C11 | O69: A22.22.3.9 - Electric Drives - Harmonic Filter - Minor Refurb | P69: 0 | Q69: 0 | R69: 396.31799 | S69: -61.192071

Sheet SAPPivot
D3: Project Definition | E3: Project Definition2 | F3: WBS Element | G3: WBS Element2 | H3: Initiative ID | I3: Sum of YTD TOTAL
D4: PROJECT 0280 | E4: PROJECT 1577 | F4: PROJECT PROJECT 000128PROJECT 0001-PROJECT 00011 | G4: Project Management | H4: INITIATIVE 00010 | I4: 0
F5: PROJECT PROJECT 000128PROJECT 0001-PROJECT 00011-PROJECT 00011-PROJECT 00012 | G5: GT Operations | H5: INITIATIVE 00010 | I5: 77127.05
F6: PROJECT PROJECT 000128PROJECT 0001-PROJECT 00011-PROJECT 00011-PROJECT 00013 | G6: NG Overhead | H6: INITIATIVE 00010 | I6: 512918.02
F7: PROJECT PROJECT 000128PROJECT 0001-PROJECT 00011-PROJECT 00011-PROJECT 00014 | G7: Delivery Unit Project Management | H7: INITIATIVE 00010 | I7: 822587.9
F8: PROJECT PROJECT 000128PROJECT 0001-PROJECT 00012-PROJECT 00011-PROJECT 00013 | G8: External Affiars | H8: INITIATIVE 00010 | I8: 598.62
F9: PROJECT PROJECT 000128PROJECT 0001-PROJECT 00012-PROJECT 00012-PROJECT 00013 | G9: Mechanical | H9: INITIATIVE 00010 | I9: 49000
F10: PROJECT PROJECT 000128PROJECT 0001-PROJECT 00012-PROJECT 00013-PROJECT 00011 | G10: Contractor Project Management | H10: INITIATIVE 00010 | I10: -4082340
F11: PROJECT PROJECT 000128PROJECT 0001-PROJECT 00012-PROJECT 00013-PROJECT 00016 | G11: All | H11: INITIATIVE 00010 | I11: 52897.09
F12: PROJECT PROJECT 000128PROJECT 0001-PROJECT 00012-PROJECT 00014-PROJECT 00016 | G12: All | H12: INITIATIVE 00010 | I12: 4111458.6
F13: PROJECT PROJECT 000128PROJECT 0001-PROJECT 00013-PROJECT 00011-PROJECT 00012 | G13: Accomodation & Facilities | H13: INITIATIVE 00010 | I13: 1071733.5
F14: PROJECT PROJECT 000128PROJECT 0001-PROJECT 00013-PROJECT 00011-PROJECT 00013 | G14: Environmental Assessment | H14: INITIATIVE 00010 | I14: -12094
F15: PROJECT PROJECT 000128PROJECT 0001-PROJECT 00014-PROJECT 00012-PROJECT 00014 | G15: Rotating | H15: INITIATIVE 00010 | I15: 6325495
F16: PROJECT PROJECT 000128PROJECT 0001-PROJECT 00017-PROJECT 00011-PROJECT 00011 | G16: Contractor Project Management | H16: INITIATIVE 00010 | I16: 10769281
D17: PROJECT 0285 | E17: PROJECT 1580 | F17: PROJECT PROJECT 0001285-PROJECT 00011-PROJECT 00011-PROJECT 00012 | G17: GT Operations | H17: INITIATIVE 00011 | I17: 11873.44
F18: PROJECT PROJECT 0001285-PROJECT 00011-PROJECT 00011-PROJECT 00013 | G18: NG Overhead | H18: INITIATIVE 00011 | I18: 25765.39
F19: PROJECT PROJECT 0001285-PROJECT 00011-PROJECT 00011-PROJECT 00014 | G19: Delivery Unit Project Management | H19: INITIATIVE 00011 | I19: 43055.39
F20: PROJECT PROJECT 0001285-PROJECT 00012-PROJECT 00012-PROJECT 00013 | G20: Mechanical | H20: INITIATIVE 00011 | I20: 327300.05
F21: PROJECT PROJECT 0001285-PROJECT 00012-PROJECT 00013-PROJECT 00016 | G21: All | H21: INITIATIVE 00011 | I21: 31398.4
D22: PROJECT 0371 | E22: PROJECT 1626 | F22: PROJECT PROJECT 0001371-PROJECT 00011-PROJECT 00011-PROJECT 00011 | G22: GT Project Management | H22: INITIATIVE 00129 | I22: -66658.8
F23: PROJECT PROJECT 0001371-PROJECT 00011-PROJECT 00011-PROJECT 00013 | G23: NG Overheads | H23: INITIATIVE 00129 | I23: -26413.59
F24: PROJECT PROJECT 0001371-PROJECT 00012-PROJECT 00012-PROJECT 00011 | G24: Contractor Project Management | H24: INITIATIVE 00129 | I24: -243120
F25: PROJECT PROJECT 0001371-PROJECT 00014-PROJECT 00011-PROJECT 00013 | G25: Consultancy Services | H25: INITIATIVE 00129 | I25: 5142.27
F26: PROJECT PROJECT 0001371-PROJECT 00017-PROJECT 00011-PROJECT 00011 | G26: Contractor Project Management | H26: INITIATIVE 00129 | I26: 8035
D27: PROJECT 0416 | E27: PROJECT 1575 | F27: PROJECT PROJECT 0001416-PROJECT 00011 | G27: Project Management | H27: INITIATIVE 00145 | I27: -18371.73
F28: PROJECT PROJECT 0001416-PROJECT 00011-PROJECT 00011-PROJECT 00011 | G28: GT Project Management | H28: INITIATIVE 00145 | I28: 142345.95
F29: PROJECT PROJECT 0001416-PROJECT 00011-PROJECT 00011-PROJECT 00012 | G29: GT Operations | H29: INITIATIVE 00145 | I29: 16468.05
F30: PROJECT PROJECT 0001416-PROJECT 00011-PROJECT 00011-PROJECT 00013 | G30: NG Overheads | H30: INITIATIVE 00145 | I30: 250984.34
F31: PROJECT PROJECT 0001416-PROJECT 00011-PROJECT 00011-PROJECT 00014 | G31: Delivery Unit Project Management | H31: INITIATIVE 00145 | I31: 374810.87
F32: PROJECT PROJECT 0001416-PROJECT 00011-PROJECT 00011-PROJECT 00016 | G32: GT System Operator | H32: INITIATIVE 00145 | I32: 1663.75
F33: PROJECT PROJECT 0001416-PROJECT 00012-PROJECT 00011-PROJECT 00011 | G33: Legal | H33: INITIATIVE 00145 | I33: 3623
F34: PROJECT PROJECT 0001416-PROJECT 00012-PROJECT 00011-PROJECT 00012 | G34: Planning Consents | H34: INITIATIVE 00145 | I34: -16425
F35: PROJECT PROJECT 0001416-PROJECT 00012-PROJECT 00011-PROJECT 00013 | G35: External Affiars | H35: INITIATIVE 00145 | I35: 12962.76
F36: PROJECT PROJECT 0001416-PROJECT 00012-PROJECT 00011-PROJECT 00014 | G36: Evironmental Impact Assessment | H36: INITIATIVE 00145 | I36: 55521.78
F37: PROJECT PROJECT 0001416-PROJECT 00012-PROJECT 00012-PROJECT 00013 | G37: Mechanical | H37: INITIATIVE 00145 | I37: 63004
F38: PROJECT PROJECT 0001416-PROJECT 00012-PROJECT 00014-PROJECT 00016 | G38: All | H38: INITIATIVE 00145 | I38: 5188858.3
F39: PROJECT PROJECT 0001416-PROJECT 00013-PROJECT 00011-PROJECT 00013 | G39: Environmental Assessment | H39: INITIATIVE 00145 | I39: 169824.58
... F44: PROJECT PROJECT 0001416-PROJECT 00017-PROJECT 00011-PROJECT 00011 | G44: Contractor Project Management | H44: INITIATIVE 00145 | I44: -469280.61
D45: PROJECT 0417 | E45: PROJECT 1638 | F45: PROJECT PROJECT 0001417-PROJECT 00011-PROJECT 00011-PROJECT 00011 | G45: GT Project Management | H45: INITIATIVE 00146 | I45: 21166.93
F46: PROJECT PROJECT 0001417-PROJECT 00011-PROJECT 00011-PROJECT 00013 | G46: NG Overheads | H46: INITIATIVE 00146 | I46: 8391.65
...

Sheet Copperleaf Data
A1: InvestmentCode | B1: InvestmentName | C1: Area | D1: Facility | E1: FinalSubmissionInvIdT3 | F1: FinalSubmissionVolumeT3 | G1: InvestmentVolume | H1: InvIdCode | I1: PriceBaseOfEnteredCost | J1: Product | K1: Site | L1: SiteId | M1: FundingPositionT3Proposed | N1: InterventionDriver | O1: SAPProject | P1: PercentageOfWBS | Q1: IDTTotalECC | R1: PACCode
A2: INITIATIVE 00347 | B2: INVESTMENT 00448 | C2: REGION 004 AND NORTH | D2: LOCATION 0033 | E2: C-PROJECT 000169 | F2: 1 | G2: 1 | H2: C-PROJECT 000169 | I2: 23/24 | J2: Rotating Machinery | K2: LOCATION 0033 | L2: SITE 00481 | M2: Baseline | N2: Legislation | Q2: 2652301.9 | R2: INITIATIVE 02056
A3: INITIATIVE 00352 | B3: INVESTMENT 00318 | C3: REGION 004 AND NORTH | D3: LOCATION 0444 | E3: C-PROJECT 000134 | F3: 1 | G3: 1 | H3: C-PROJECT 000134 | I3: 23/24 | J3: LOCATION 9001 | K3: LOCATION 0444 | L3: SITE 00382 | M3: Baseline | N3: Defects | O3: PROJECT 1276 | P3: 84.2926 | Q3: 560121.33 | R3: INITIATIVE 02237
A4: INITIATIVE 00353 | B4: INVESTMENT 00579 | C4: SITE 00554 | D4: LOCATION 0546 | E4: C-PROJECT 000172 | F4: 1 | G4: 1 | H4: C-PROJECT 000172 | I4: 23/24 | J4: Rotating Machinery | K4: LOCATION 0546 | L4: SITE 00470 | M4: Baseline | N4: Legislation | O4: PROJECT 0700 | P4: 43.5841 | Q4: 554520.11 | R4: INITIATIVE 02000
A5: INITIATIVE 00356 | B5: INVESTMENT 00441 | C5: SITE 00554 | D5: LOCATION 0017 | E5: C-PROJECT 000173 | F5: 1 | G5: 1 | H5: C-PROJECT 000173 | I5: 23/24 | J5: Rotating Machinery | K5: LOCATION 0017 | L5: SITE 00454 | M5: Baseline | N5: Legislation | O5: PROJECT 0694 | P5: 44.2913 | Q5: 1371661 | R5: INITIATIVE 02000
A6: INITIATIVE 00359 | B6: INVESTMENT 00489 | C6: SITE 00058 | D6: LOCATION 0123 | E6: C-PROJECT 000175 | F6: 1 | G6: 1 | H6: C-PROJECT 000175 | I6: 23/24 | J6: Rotating Machinery | K6: LOCATION 0123 | L6: SITE 00460 | M6: Baseline | N6: Legislation | Q6: 231013.78 | R6: INITIATIVE 02055
A7: INITIATIVE 00370 | B7: INVESTMENT 00546 | C7: SITE 00554 | D7: LOCATION 0308 | E7: C-PROJECT 000187 | F7: 1 | G7: 1 | H7: C-PROJECT 000187 | I7: 23/24 | J7: Valves | K7: LOCATION 0308 | L7: SITE 00477 | M7: Baseline | N7: Fixed Time Interval | Q7: 98181.23 | R7: INITIATIVE 02054
A8: INITIATIVE 00372 | B8: INVESTMENT 00525 | C8: SITE 00058 | D8: LOCATION 0282 | E8: C-PROJECT 000194 | F8: 1 | G8: 1 | H8: C-PROJECT 000194 | I8: 23/24 | J8: Compressor Fleet | K8: LOCATION 0282 | L8: SITE 00456 | M8: RIIO T2 - UM | O8: PROJECT 0285 | P8: 25 | Q8: 4.221PROJECT 0001493458E7 | R8: INITIATIVE 01837
A9: INITIATIVE 00373 | B9: INVESTMENT 00523 | C9: SITE 00058 | D9: LOCATION 0282 | E9: C-PROJECT 000194 | F9: 0 | G9: 0 | H9: C-PROJECT 000194 | I9: 18/19 | J9: Compressor Fleet | K9: LOCATION 0282 | L9: SITE 00456 | M9: RIIO T2 - UM | O9: PROJECT 0417 | P9: 50 | Q9: 0 | R9: INITIATIVE 01975
A10: INITIATIVE 00374 | B10: INVESTMENT 00522 | C10: SITE 00058 | D10: LOCATION 0282 | E10: C-PROJECT 000194 | F10: 0 | G10: 0 | H10: C-PROJECT 000194 | I10: 18/19 | J10: Compressor Fleet | K10: LOCATION 0282 | L10: SITE 00456 | M10: RIIO T2 - UM | O10: PROJECT 0285 | P10: 25 | Q10: 0 | R10: INITIATIVE 01837
A11: INITIATIVE 00377 | B11: INVESTMENT 00513 | C11: SITE 00058 | D11: LOCATION 0266 | G11: 0 | H11: C-PROJECT 000197 | J11: Compressor Fleet | K11: LOCATION 0266 | L11: SITE 00455 | M11: RIIO T2 - UM | Q11: 0 | R11: INITIATIVE 02057
A12: INITIATIVE 00379 | B12: INVESTMENT 00435 | C12: SITE 00554 | D12: LOCATION 0017 | E12: C-PROJECT 000176 | F12: 1 | G12: 1 | H12: C-PROJECT 000176 | I12: 23/24 | J12: Rotating Machinery | K12: LOCATION 0017 | L12: SITE 00454 | M12: Baseline | N12: Defects | O12: PROJECT 0694 | P12: 1.5449 | Q12: 47843.925 | R12: INITIATIVE 02000
A13: INITIATIVE 00383 | B13: INVESTMENT 00483 | C13: SITE 00058 | D13: LOCATION 0108 | E13: C-PROJECT 000176 | F13: 1 | G13: 1 | H13: C-PROJECT 000176 | I13: 23/24 | J13: Rotating Machinery | K13: LOCATION 0108 | L13: SITE 00461 | M13: Baseline | N13: Defects | O13: PROJECT 0628 | P13: 33.33 | Q13: 47843.925 | R13: INITIATIVE 02069
A14: INITIATIVE 00389 | B14: INVESTMENT 00576 | C14: SITE 00554 | D14: LOCATION 0546 | E14: C-PROJECT 000195 | F14: 1 | G14: 1 | H14: C-PROJECT 000195 | I14: 23/24 | J14: Compressor Fleet | K14: LOCATION 0546 | L14: SITE 00470 | M14: RIIO T2 - UM | O14: PROJECT 0416 | P14: 100 | Q14: 5.54197169PROJECT 00014E7 | R14: INITIATIVE 01833
A15: INITIATIVE 00391 | B15: INVESTMENT 00575 | C15: SITE 00554 | D15: LOCATION 0546 | E15: C-PROJECT 000195 | F15: 0 | G15: 0 | H15: C-PROJECT 000195 | J15: Compressor Fleet | K15: LOCATION 0546 | L15: SITE 00470 | M15: RIIO T2 - UM | O15: PROJECT 0437 | P15: 50 | Q15: 0 | R15: INITIATIVE 01993
A16: INITIATIVE 00393 | B16: INVESTMENT 00450 | C16: REGION 004 AND NORTH | D16: LOCATION 0033 | E16: C-333 | F16: 1 | G16: 1 | H16: C-333 | I16: 23/24 | J16: Compressor Fleet | K16: LOCATION 0033 | L16: SITE 00481 | M16: Baseline | N16: Defects | Q16: 2044410.1 | R16: INITIATIVE 02056
A17: INITIATIVE 00394 | B17: INVESTMENT 00460 | C17: REGION 004 AND NORTH | D17: LOCATION 0069 | E17: C-333 | F17: 1 | G17: 1 | H17: C-333 | I17: 23/24 | J17: Compressor Fleet | K17: LOCATION 0069 | L17: SITE 00462 | M17: Baseline | N17: Defects | Q17: 2044410.1 | R17: INITIATIVE 02056
A18: INITIATIVE 00397 | B18: INVESTMENT 00437 | C18: SITE 00554 | D18: LOCATION 0017 | E18: C-196 | F18: 1 | G18: 1 | H18: C-196 | I18: 23/24 | J18: Rotating Machinery | K18: LOCATION 0017 | L18: SITE 00454 | M18: Baseline | N18: Defects | O18: PROJECT 0694 | P18: 4.5837 | Q18: 141951.57 | R18: INITIATIVE 02000
A19: INITIATIVE 00399 | B19: INVESTMENT 00454 | C19: SITE 00554 | D19: LOCATION 0037 | E19: C-196 | F19: 1 | G19: 1 | H19: C-196 | I19: 23/24 | J19: Rotating Machinery | K19: LOCATION 0037 | L19: SITE 00472 | M19: Baseline | N19: Defects | O19: PROJECT 0695 | P19: 10.8087 | Q19: 141951.57 | R19: INITIATIVE 02000
A20: INITIATIVE 00404 | B20: INVESTMENT 00492 | C20: SITE 00058 | D20: LOCATION 0123 | E20: C-196 | F20: 1 | G20: 1 | H20: C-196 | I20: 23/24 | J20: Rotating Machinery | K20: LOCATION 0123 | L20: SITE 00460 | M20: Baseline | N20: Defects | Q20: 141951.57 | R20: INITIATIVE 02055
A21: INITIATIVE 00405 | B21: INVESTMENT 00498 | C21: SITE 00058 | D21: LOCATION 0156 | E21: C-196 | F21: 1 | G21: 1 | H21: C-196 | I21: 23/24 | J21: Rotating Machinery | K21: LOCATION 0156 | L21: SITE 00459 | M21: Baseline | N21: Defects | Q21: 141951.57 | R21: INITIATIVE 02055
A22: INITIATIVE 00407 | B22: INVESTMENT 00505 | C22: SITE 00058 | D22: LOCATION 0156 | E22: C-196 | F22: 1 | G22: 1 | H22: C-196 | I22: 23/24 | J22: Rotating Machinery | K22: LOCATION 0156 | L22: SITE 00459 | M22: Baseline | N22: Defects | Q22: 141951.57 | R22: INITIATIVE 02055
A23: INITIATIVE 00411 | B23: INVESTMENT 00663 | C23: SITE 00554 | D23: LOCATION 0037 | E23: C-PROJECT 000175 | F23: 1 | G23: 1 | H23: C-PROJECT 000175 | I23: 23/24 | J23: Rotating Machinery | K23: LOCATION 0037 | L23: SITE 00472 | M23: Baseline | N23: Legislation | O23: PROJECT 0695 | P23: 17.5902 | Q23: 231013.78 | R23: INITIATIVE 02000
A24: INITIATIVE 00415 | B24: INVESTMENT 00040 | C24: SITE 00554 | D24: LOCATION 0017 | E24: C-177 | F24: 1 | G24: 1 | H24: C-177 | I24: 23/24 | J24: Cabs | K24: LOCATION 0017 | L24: SITE 00454 | M24: Baseline | N24: Defects | O24: 0 | P24: 0 | Q24: 638520.86 | R24: INITIATIVE 02054
A25: INITIATIVE 00416 | B25: INVESTMENT 00186 | C25: SITE 00554 | D25: LOCATION 0198 | E25: C-177 | F25: 1 | G25: 1 | H25: C-177 | I25: 23/24 | J25: Cabs | K25: LOCATION 0198 | L25: SITE 00482 | M25: Baseline | N25: Defects | O25: 0 | P25: 0 | Q25: 638520.86 | R25: INITIATIVE 02054
A26: INITIATIVE 00417 | B26: INVESTMENT 00187 | C26: SITE 00554 | D26: LOCATION 0198 | E26: C-177 | F26: 1 | G26: 1 | H26: C-177 | I26: 23/24 | J26: Cabs | K26: LOCATION 0198 | L26: SITE 00482 | M26: Baseline | N26: Defects | O26: 0 | P26: 0 | Q26: 638520.86 | R26: INITIATIVE 02054
A27: INITIATIVE 00422 | B27: INVESTMENT 00241 | C27: SITE 00554 | D27: LOCATION 0351 | E27: C-177 | F27: 1 | G27: 1 | H27: C-177 | I27: 23/24 | J27: Cabs | K27: LOCATION 0351 | L27: SITE 00480 | M27: Baseline | N27: Defects | O27: PROJECT 0915 | P27: 50 | Q27: 638520.86 | R27: INITIATIVE 02052
A28: INITIATIVE 00431 | B28: INVESTMENT 00041 | C28: SITE 00554 | D28: LOCATION 0017 | E28: C-PROJECT 0001PROJECT 00014 | F28: 1 | G28: 1 | H28: C-PROJECT 0001PROJECT 00014 | I28: 23/24 | J28: Cabs | K28: LOCATION 0017 | L28: SITE 00454 | M28: Baseline | N28: Defects | O28: 0 | P28: 0 | Q28: 2074375.2 | R28: INITIATIVE 02054
A29: INITIATIVE 00432 | B29: INVESTMENT 00072 | C29: REGION 004 AND NORTH | D29: LOCATION 0069 | E29: C-PROJECT 0001PROJECT 00014 | F29: 1 | G29: 1 | H29: C-PROJECT 0001PROJECT 00014 | I29: 23/24 | J29: Cabs | K29: LOCATION 0069 | L29: SITE 00462 | M29: Baseline | N29: Defects | O29: PROJECT 0371 | P29: 24.55 | Q29: 2074375.2 | R29: INITIATIVE 01912
A30: INITIATIVE 00434 | B30: INVESTMENT 00238 | C30: SITE 00554 | D30: LOCATION 0351 | E30: C-PROJECT 0001PROJECT 00014 | F30: 1 | G30: 1 | H30: C-PROJECT 0001PROJECT 00014 | I30: 23/24 | J30: Cabs | K30: LOCATION 0351 | L30: SITE 00480 | M30: Baseline | N30: Defects | O30: 0 | P30: 0 | Q30: 2074375.2 | R30: INITIATIVE 02054
A31: INITIATIVE 00436 | B31: INVESTMENT 00422 | C31: REGION 004 AND NORTH | D31: LOCATION 0544 | E31: C-PROJECT 0001PROJECT 00018 | F31: 1 | G31: 1 | H31: C-PROJECT 0001PROJECT 00018 | I31: 23/24 | J31: Cabs | K31: LOCATION 0544 | L31: SITE 00464 | M31: Baseline | N31: Fixed Time Interval | O31: PROJECT 0371 | P31: 0.28 | Q31: 23882.884 | R31: INITIATIVE 01912
A32: INITIATIVE 00437 | B32: INVESTMENT 00423 | C32: REGION 004 AND NORTH | D32: LOCATION 0544 | E32: C-PROJECT 0001PROJECT 00018 | F32: 1 | G32: 1 | H32: C-PROJECT 0001PROJECT 00018 | I32: 23/24 | J32: Cabs | K32: LOCATION 0544 | L32: SITE 00464 | M32: Baseline | N32: Fixed Time Interval | O32: PROJECT 0371 | P32: 0.28 | Q32: 23882.884 | R32: INITIATIVE 01912
A33: INITIATIVE 00439 | B33: INVESTMENT 00196 | C33: SITE 00058 | D33: LOCATION 0240 | E33: C-PROJECT 0001PROJECT 00018 | F33: 1 | G33: 1 | H33: C-PROJECT 0001PROJECT 00018 | I33: 23/24 | J33: Cabs | K33: LOCATION 0240 | L33: SITE 00473 | M33: Baseline | N33: Fixed Time Interval | O33: PROJECT 0926 | P33: 100 | Q33: 23882.884 | R33: INITIATIVE 02051
A34: INITIATIVE 00442 | B34: INVESTMENT 00104 | C34: SITE 00554 | D34: LOCATION 0130 | E34: C-PROJECT 0001PROJECT 00018 | F34: 1 | G34: 1 | H34: C-PROJECT 0001PROJECT 00018 | I34: 23/24 | J34: Cabs | K34: LOCATION 0130 | L34: SITE 00457 | M34: Baseline | N34: Fixed Time Interval | O34: 0 | P34: 0 | Q34: 23882.884 | R34: INITIATIVE 02054
A35: INITIATIVE 00446 | B35: INVESTMENT 00044 | C35: SITE 00554 | D35: LOCATION 0037 | E35: C-PROJECT 0001PROJECT 00018 | F35: 1 | G35: 1 | H35: C-PROJECT 0001PROJECT 00018 | I35: 23/24 | J35: Cabs | K35: LOCATION 0037 | L35: SITE 00472 | M35: Baseline | N35: Fixed Time Interval | O35: 0 | P35: 0 | Q35: 23882.884 | R35: INITIATIVE 02054
A36: INITIATIVE 00448 | B36: INVESTMENT 00206 | C36: SITE 00058 | D36: LOCATION 0240 | E36: C-195 | F36: 1 | G36: 1 | H36: C-195 | I36: 23/24 | J36: Rotating Machinery | K36: LOCATION 0240 | L36: SITE 00473 | M36: Baseline | N36: Usage Based Interval | Q36: 72250.125 | R36: INITIATIVE 02055
A37: INITIATIVE 00450 | B37: INVESTMENT 00117 | C37: SITE 00554 | D37: LOCATION 0130 | E37: C-186 | F37: 1 | G37: 1 | H37: C-186 | I37: 23/24 | J37: Rotating Machinery | K37: LOCATION 0130 | L37: SITE 00457 | M37: Baseline | N37: Fixed Time Interval | O37: PROJECT 0697 | P37: 40.0318 | Q37: 72369.413 | R37: INITIATIVE 02000
A38: INITIATIVE 00451 | B38: INVESTMENT 00205 | C38: SITE 00058 | D38: LOCATION 0240 | E38: C-186 | F38: 1 | G38: 1 | H38: C-186 | I38: 23/24 | J38: Rotating Machinery | K38: LOCATION 0240 | L38: SITE 00473 | M38: Baseline | N38: Fixed Time Interval | Q38: 72369.413 | R38: INITIATIVE 02055
A39: INITIATIVE 00455 | B39: INVESTMENT 00204 | C39: SITE 00058 | D39: LOCATION 0240 | E39: C-185 | F39: 1 | G39: 1 | H39: C-185 | I39: 23/24 | J39: Rotating Machinery | K39: LOCATION 0240 | L39: SITE 00473 | M39: Baseline | N39: Fixed Time Interval | Q39: 77812.107 | R39: INITIATIVE 02055
A40: INITIATIVE 00457 | B40: INVESTMENT 00118 | C40: SITE 00554 | D40: LOCATION 0130 | E40: C-133 | F40: 1 | G40: 1 | H40: C-133 | I40: 23/24 | J40: Rotating Machinery | K40: LOCATION 0130 | L40: SITE 00457 | M40: Baseline | N40: Obsolescence | O40: PROJECT 0697 | P40: 30.1964 | Q40: 54588.914 | R40: INITIATIVE 02000
...

Sheet CopperPivot
D3: FinalSubmissionInvIdT3 | E3: FinalSubmissionVolumeT3 | F3: InvestmentCode | G3: InvestmentName | H3: PACCode | I3: SAPProject | J3: PercentageOfWBS | K3: Sum of IDTTotalECC
D4: C-133 | E4: 1 | F4: INITIATIVE 00457 | G4: INVESTMENT 00118 | H4: INITIATIVE 02000 | I4: PROJECT 0697 | J4: 30.1964 | K4: 54588.914
F5: INITIATIVE 00460 | G5: INVESTMENT 00225 | H5: INITIATIVE 02056 | I5: (blank) | J5: (blank) | K5: 54588.914
F6: INITIATIVE 00461 | G6: INVESTMENT 00428 | H6: INITIATIVE 02000 | I6: PROJECT 0700 | J6: 4.2906 | K6: 54588.914
D7: C-177 | E7: 1 | F7: INITIATIVE 00415 | G7: INVESTMENT 00040 | H7: INITIATIVE 02054 | I7: 0 | J7: 0 | K7: 638520.86
F8: INITIATIVE 00416 | G8: INVESTMENT 00186 | H8: INITIATIVE 02054 | I8: 0 | J8: 0 | K8: 638520.86
F9: INITIATIVE 00417 | G9: INVESTMENT 00187 | H9: INITIATIVE 02054 | I9: 0 | J9: 0 | K9: 638520.86
F10: INITIATIVE 00422 | G10: INVESTMENT 00241 | H10: INITIATIVE 02052 | I10: PROJECT 0915 | J10: 50 | K10: 638520.86
D11: C-185 | E11: 1 | F11: INITIATIVE 00455 | G11: INVESTMENT 00204 | H11: INITIATIVE 02055 | I11: (blank) | J11: (blank) | K11: 77812.107
D12: C-186 | E12: 1 | F12: INITIATIVE 00450 | G12: INVESTMENT 00117 | H12: INITIATIVE 02000 | I12: PROJECT 0697 | J12: 40.0318 | K12: 72369.413
F13: INITIATIVE 00451 | G13: INVESTMENT 00205 | H13: INITIATIVE 02055 | I13: (blank) | J13: (blank) | K13: 72369.413
D14: C-195 | E14: 1 | F14: INITIATIVE 00448 | G14: INVESTMENT 00206 | H14: INITIATIVE 02055 | I14: (blank) | J14: (blank) | K14: 72250.125
D15: C-196 | E15: 1 | F15: INITIATIVE 00397 | G15: INVESTMENT 00437 | H15: INITIATIVE 02000 | I15: PROJECT 0694 | J15: 4.5837 | K15: 141951.57
F16: INITIATIVE 00399 | G16: INVESTMENT 00454 | H16: INITIATIVE 02000 | I16: PROJECT 0695 | J16: 10.8087 | K16: 141951.57
F17: INITIATIVE 00404 | G17: INVESTMENT 00492 | H17: INITIATIVE 02055 | I17: (blank) | J17: (blank) | K17: 141951.57
F18: INITIATIVE 00405 | G18: INVESTMENT 00498 | H18: INITIATIVE 02055 | I18: (blank) | J18: (blank) | K18: 141951.57
F19: INITIATIVE 00407 | G19: INVESTMENT 00505 | H19: INITIATIVE 02055 | I19: (blank) | J19: (blank) | K19: 141951.57
D20: C-333 | E20: 1 | F20: INITIATIVE 00393 | G20: INVESTMENT 00450 | H20: INITIATIVE 02056 | I20: (blank) | J20: (blank) | K20: 2044410.1
F21: INITIATIVE 00394 | G21: INVESTMENT 00460 | H21: INITIATIVE 02056 | I21: (blank) | J21: (blank) | K21: 2044410.1
D22: (blank) | E22: (blank) | F22: INITIATIVE 00377 | G22: INVESTMENT 00513 | H22: INITIATIVE 02057 | I22: (blank) | J22: (blank) | K22: 0
F23: (blank) | G23: (blank) | H23: (blank) | I23: (blank) | J23: (blank)
D24: C-PROJECT 000169 | E24: 1 | F24: INITIATIVE 00347 | G24: INVESTMENT 00448 | H24: INITIATIVE 02056 | I24: (blank) | J24: (blank) | K24: 2652301.9
D25: C-PROJECT 000134 | E25: 1 | F25: INITIATIVE 00352 | G25: INVESTMENT 00318 | H25: INITIATIVE 02237 | I25: PROJECT 1276 | J25: 84.2926 | K25: 560121.33
D26: C-PROJECT 000172 | E26: 1 | F26: INITIATIVE 00353 | G26: INVESTMENT 00579 | H26: INITIATIVE 02000 | I26: PROJECT 0700 | J26: 43.5841 | K26: 554520.11
D27: C-PROJECT 000173 | E27: 1 | F27: INITIATIVE 00356 | G27: INVESTMENT 00441 | H27: INITIATIVE 02000 | I27: PROJECT 0694 | J27: 44.2913 | K27: 1371661
D28: C-PROJECT 000175 | E28: 1 | F28: INITIATIVE 00359 | G28: INVESTMENT 00489 | H28: INITIATIVE 02055 | I28: (blank) | J28: (blank) | K28: 231013.78
F29: INITIATIVE 00411 | G29: INVESTMENT 00663 | H29: INITIATIVE 02000 | I29: PROJECT 0695 | J29: 17.5902 | K29: 231013.78
D30: C-PROJECT 000187 | E30: 1 | F30: INITIATIVE 00370 | G30: INVESTMENT 00546 | H30: INITIATIVE 02054 | I30: (blank) | J30: (blank) | K30: 98181.23
D31: C-PROJECT 000194 | E31: 0 | F31: INITIATIVE 00373 | G31: INVESTMENT 00523 | H31: INITIATIVE 01975 | I31: PROJECT 0417 | J31: 50 | K31: 0
F32: INITIATIVE 00374 | G32: INVESTMENT 00522 | H32: INITIATIVE 01837 | I32: PROJECT 0285 | J32: 25 | K32: 0
E33: 1 | F33: INITIATIVE 00372 | G33: INVESTMENT 00525 | H33: INITIATIVE 01837 | I33: PROJECT 0285 | J33: 25 | K33: 0
D34: C-PROJECT 000176 | E34: 1 | F34: INITIATIVE 00379 | G34: INVESTMENT 00435 | H34: INITIATIVE 02000 | I34: PROJECT 0694 | J34: 1.5449 | K34: 47843.925
F35: INITIATIVE 00383 | G35: INVESTMENT 00483 | H35: INITIATIVE 02069 | I35: PROJECT 0628 | J35: 33.33 | K35: 47843.925
D36: C-PROJECT 000195 | E36: 0 | F36: INITIATIVE 00391 | G36: INVESTMENT 00575 | H36: INITIATIVE 01993 | I36: PROJECT 0437 | J36: 50 | K36: 0
E37: 1 | F37: INITIATIVE 00389 | G37: INVESTMENT 00576 | H37: INITIATIVE 01833 | I37: PROJECT 0416 | J37: 100 | K37: 0
D38: C-PROJECT 0001PROJECT 00014 | E38: 1 | F38: INITIATIVE 00431 | G38: INVESTMENT 00041 | H38: INITIATIVE 02054 | I38: 0 | J38: 0 | K38: 2074375.2
F39: INITIATIVE 00432 | G39: INVESTMENT 00072 | H39: INITIATIVE 01912 | I39: PROJECT 0371 | J39: 24.55 | K39: 2074375.2
F40: INITIATIVE 00434 | G40: INVESTMENT 00238 | H40: INITIATIVE 02054 | I40: 0 | J40: 0 | K40: 2074375.2
D41: C-PROJECT 0001PROJECT 00018 | E41: 1 | F41: INITIATIVE 00436 | G41: INVESTMENT 00422 | H41: INITIATIVE 01912 | I41: PROJECT 0371 | J41: 0.28 | K41: 23882.884
F42: INITIATIVE 00437 | G42: INVESTMENT 00423 | H42: INITIATIVE 01912 | I42: PROJECT 0371 | J42: 0.28 | K42: 23882.884
...

Sheet PO Summary
A1: Sample Summary-Level Purchase Orders
A2: Synthetic PoC data: POs are raised above WBS level and allocated across projects/WBS in the Actual Allocation sheet.
A4: PO Number | B4: Supplier ID | C4: Contract Ref | D4: PO Description | E4: PO Date | F4: Currency | G4: Posting Level | H4: Summary Cost Object | I4: PO Value (£) | J4: Actual Posted (£) | K4: Allocation Basis | L4: Status | M4: Total Allocation % | N4: Allocated Actual (£) | O4: Unallocated Difference (£)
A5: PO-SAMPLE-001 | B5: SUPPLIER 001 | C5: CONTRACT 001 | D5: Programme engineering services | E5: 46127 | F5: GBP | G5: Summary / programme | H5: MULTI-PROJECT | I5: 1250000 | J5: 980000 | K5: Planned effort % | L5: Open / partly invoiced | M5: =SUMIF('Actual Allocation'!$B:$B,A5,'Actual Allocation'!$I:$I) -> 1 | N5: =SUMIF('Actual Allocation'!$B:$B,A5,'Actual Allocation'!$M:$M) -> 980000 | O5: =J5-N5 -> 0
A6: PO-SAMPLE-002 | B6: SUPPLIER 002 | C6: CONTRACT 002 | D6: Regional construction framework | E6: 46162 | F6: GBP | G6: Summary / programme | H6: MULTI-PROJECT | I6: 2100000 | J6: 1525000 | K6: Forecast ETC % | L6: Open / partly invoiced | M6: =SUMIF('Actual Allocation'!$B:$B,A6,'Actual Allocation'!$I:$I) -> 1 | N6: =SUMIF('Actual Allocation'!$B:$B,A6,'Actual Allocation'!$M:$M) -> 1525000 | O6: =J6-N6 -> 0
A7: PO-SAMPLE-003 | B7: SUPPLIER 003 | C7: CONTRACT 003 | D7: Shared project management services | E7: 46185 | F7: GBP | G7: Summary / programme | H7: MULTI-PROJECT | I7: 720000 | J7: 615000 | K7: Headcount / timesheet % | L7: Open / partly invoiced | M7: =SUMIF('Actual Allocation'!$B:$B,A7,'Actual Allocation'!$I:$I) -> 1 | N7: =SUMIF('Actual Allocation'!$B:$B,A7,'Actual Allocation'!$M:$M) -> 615000 | O7: =J7-N7 -> 0
A8: PO-SAMPLE-004 | B8: SUPPLIER 004 | C8: CONTRACT 004 | D8: Mechanical works call-off | E8: 46211 | F8: GBP | G8: Summary / programme | H8: MULTI-PROJECT | I8: 1850000 | J8: 1340000 | K8: Activity quantity % | L8: Open / partly invoiced | M8: =SUMIF('Actual Allocation'!$B:$B,A8,'Actual Allocation'!$I:$I) -> 1 | N8: =SUMIF('Actual Allocation'!$B:$B,A8,'Actual Allocation'!$M:$M) -> 1340000 | O8: =J8-N8 -> 0
A9: PO-SAMPLE-005 | B9: SUPPLIER 005 | C9: CONTRACT 005 | D9: Environmental and consenting services | E9: 46252 | F9: GBP | G9: Summary / programme | H9: MULTI-PROJECT | I9: 540000 | J9: 420000 | K9: Approved budget % | L9: Open / partly invoiced | M9: =SUMIF('Actual Allocation'!$B:$B,A9,'Actual Allocation'!$I:$I) -> 1 | N9: =SUMIF('Actual Allocation'!$B:$B,A9,'Actual Allocation'!$M:$M) -> 420000 | O9: =J9-N9 -> 0
A10: PO-SAMPLE-006 | B10: SUPPLIER 006 | C10: CONTRACT 006 | D10: Portfolio assurance support | E10: 46268 | F10: GBP | G10: Summary / programme | H10: MULTI-PROJECT | I10: 390000 | J10: 315000 | K10: Equal allocation | L10: Open / partly invoiced | M10: =SUMIF('Actual Allocation'!$B:$B,A10,'Actual Allocation'!$I:$I) -> 1 | N10: =SUMIF('Actual Allocation'!$B:$B,A10,'Actual Allocation'!$M:$M) -> 315000 | O10: =J10-N10 -> 0

Sheet Actual Allocation
A1: Manual Actual Cost Allocation Across Projects and WBS
A2: Enter or adjust Allocation % and Manual Adjustment. Formula fields recalculate the final actual by WBS.
A4: Allocation ID | B4: PO Number | C4: Project Definition | D4: Project Name | E4: WBS Element | F4: WBS Description | G4: Investment ID | H4: Allocation Rule | I4: Allocation % | J4: PO Actual (£) | K4: Calculated Allocation (£) | L4: Manual Adjustment (£) | M4: Final Allocated Actual (£) | N4: Allocation Rationale | O4: Review Status
A5: ALLOC-001-01 | B5: PO-SAMPLE-001 | C5: PROJECT 0280 | D5: PROJECT 1577 | E5: PROJECT PROJECT 000128PROJECT 0001-PROJECT 00011 | F5: Project Management | G5: INITIATIVE 00010 | H5: Planned effort % | I5: 0.4 | J5: =VLOOKUP(B5,'PO Summary'!$A:$O,10,FALSE) -> 980000 | K5: =I5*J5 -> 392000 | L5: 0 | M5: =K5+L5 -> 392000 | N5: Sample rule; amend where business evidence supports a different split | O5: For review
A6: ALLOC-001-02 | B6: PO-SAMPLE-001 | C6: PROJECT 0280 | D6: PROJECT 1577 | E6: PROJECT PROJECT 000128PROJECT 0001-PROJECT 00011-PROJECT 00011-PROJECT 00013 | F6: NG Overhead | G6: INITIATIVE 00010 | H6: Planned effort % | I6: 0.35 | J6: =VLOOKUP(B6,'PO Summary'!$A:$O,10,FALSE) -> 980000 | K6: =I6*J6 -> 343000 | L6: 0 | M6: =K6+L6 -> 343000 | N6: Sample rule; amend where business evidence supports a different split | O6: For review
A7: ALLOC-001-03 | B7: PO-SAMPLE-001 | C7: PROJECT 0285 | D7: PROJECT 1580 | E7: PROJECT PROJECT 0001285-PROJECT 00011-PROJECT 00011-PROJECT 00013 | F7: NG Overhead | G7: INITIATIVE 00011 | H7: Planned effort % | I7: 0.25 | J7: =VLOOKUP(B7,'PO Summary'!$A:$O,10,FALSE) -> 980000 | K7: =I7*J7 -> 245000 | L7: 0 | M7: =K7+L7 -> 245000 | N7: Sample rule; amend where business evidence supports a different split | O7: For review
A8: ALLOC-002-01 | B8: PO-SAMPLE-002 | C8: PROJECT 0285 | D8: PROJECT 1580 | E8: PROJECT PROJECT 0001285-PROJECT 00011-PROJECT 00011-PROJECT 00012 | F8: GT Operations | G8: INITIATIVE 00011 | H8: Forecast ETC % | I8: 0.5 | J8: =VLOOKUP(B8,'PO Summary'!$A:$O,10,FALSE) -> 1525000 | K8: =I8*J8 -> 762500 | L8: 0 | M8: =K8+L8 -> 762500 | N8: Sample rule; amend where business evidence supports a different split | O8: For review
A9: ALLOC-002-02 | B9: PO-SAMPLE-002 | C9: PROJECT 0285 | D9: PROJECT 1580 | E9: PROJECT PROJECT 0001285-PROJECT 00011-PROJECT 00011-PROJECT 00014 | F9: Delivery Unit Project Management | G9: INITIATIVE 00011 | H9: Forecast ETC % | I9: 0.3 | J9: =VLOOKUP(B9,'PO Summary'!$A:$O,10,FALSE) -> 1525000 | K9: =I9*J9 -> 457500 | L9: 0 | M9: =K9+L9 -> 457500 | N9: Sample rule; amend where business evidence supports a different split | O9: For review
A10: ALLOC-002-03 | B10: PO-SAMPLE-002 | C10: PROJECT 0371 | D10: PROJECT 1626 | E10: PROJECT PROJECT 0001371-PROJECT 00011-PROJECT 00011-PROJECT 00013 | F10: NG Overheads | G10: INITIATIVE 00129 | H10: Forecast ETC % | I10: 0.2 | J10: =VLOOKUP(B10,'PO Summary'!$A:$O,10,FALSE) -> 1525000 | K10: =I10*J10 -> 305000 | L10: 0 | M10: =K10+L10 -> 305000 | N10: Sample rule; amend where business evidence supports a different split | O10: For review
A11: ALLOC-003-01 | B11: PO-SAMPLE-003 | C11: PROJECT 0371 | D11: PROJECT 1626 | E11: PROJECT PROJECT 0001371-PROJECT 00011-PROJECT 00011-PROJECT 00011 | F11: GT Project Management | G11: INITIATIVE 00129 | H11: Headcount / timesheet % | I11: 0.6 | J11: =VLOOKUP(B11,'PO Summary'!$A:$O,10,FALSE) -> 615000 | K11: =I11*J11 -> 369000 | L11: 0 | M11: =K11+L11 -> 369000 | N11: Sample rule; amend where business evidence supports a different split | O11: For review
A12: ALLOC-003-02 | B12: PO-SAMPLE-003 | C12: PROJECT 0371 | D12: PROJECT 1626 | E12: PROJECT PROJECT 0001371-PROJECT 00012-PROJECT 00012-PROJECT 00011 | F12: Contractor Project Management | G12: INITIATIVE 00129 | H12: Headcount / timesheet % | I12: 0.4 | J12: =VLOOKUP(B12,'PO Summary'!$A:$O,10,FALSE) -> 615000 | K12: =I12*J12 -> 246000 | L12: 0 | M12: =K12+L12 -> 246000 | N12: Sample rule; amend where business evidence supports a different split | O12: For review
A13: ALLOC-004-01 | B13: PO-SAMPLE-004 | C13: PROJECT 0416 | D13: PROJECT 1575 | E13: PROJECT PROJECT 0001416-PROJECT 00011 | F13: Project Management | G13: INITIATIVE 00145 | H13: Activity quantity % | I13: 0.45 | J13: =VLOOKUP(B13,'PO Summary'!$A:$O,10,FALSE) -> 1340000 | K13: =I13*J13 -> 603000 | L13: 0 | M13: =K13+L13 -> 603000 | N13: Sample rule; amend where business evidence supports a different split | O13: For review
A14: ALLOC-004-02 | B14: PO-SAMPLE-004 | C14: PROJECT 0416 | D14: PROJECT 1575 | E14: PROJECT PROJECT 0001416-PROJECT 00011-PROJECT 00011-PROJECT 00012 | F14: GT Operations | G14: INITIATIVE 00145 | H14: Activity quantity % | I14: 0.3 | J14: =VLOOKUP(B14,'PO Summary'!$A:$O,10,FALSE) -> 1340000 | K14: =I14*J14 -> 402000 | L14: 0 | M14: =K14+L14 -> 402000 | N14: Sample rule; amend where business evidence supports a different split | O14: For review
A15: ALLOC-004-03 | B15: PO-SAMPLE-004 | C15: PROJECT 0417 | D15: PROJECT 1638 | E15: PROJECT PROJECT 0001417-PROJECT 00011-PROJECT 00011-PROJECT 00013 | F15: NG Overheads | G15: INITIATIVE 00146 | H15: Activity quantity % | I15: 0.25 | J15: =VLOOKUP(B15,'PO Summary'!$A:$O,10,FALSE) -> 1340000 | K15: =I15*J15 -> 335000 | L15: 0 | M15: =K15+L15 -> 335000 | N15: Sample rule; amend where business evidence supports a different split | O15: For review
A16: ALLOC-005-01 | B16: PO-SAMPLE-005 | C16: PROJECT 0417 | D16: PROJECT 1638 | E16: PROJECT PROJECT 0001417-PROJECT 00011-PROJECT 00011-PROJECT 00011 | F16: GT Project Management | G16: INITIATIVE 00146 | H16: Approved budget % | I16: 0.55 | J16: =VLOOKUP(B16,'PO Summary'!$A:$O,10,FALSE) -> 420000 | K16: =I16*J16 -> 231000 | L16: 0 | M16: =K16+L16 -> 231000 | N16: Sample rule; amend where business evidence supports a different split | O16: For review
... A20: ALLOC-006-02 | B20: PO-SAMPLE-006 | C20: PROJECT 0437 | D20: PROJECT 1658 | E20: PROJECT PROJECT 0001437-PROJECT 00011-PROJECT 00011-PROJECT 00013 | F20: NG Overheads | G20: INITIATIVE 00160 | H20: Equal allocation | I20: 0.5 | J20: =VLOOKUP(B20,'PO Summary'!$A:$O,10,FALSE) -> 315000 | K20: =I20*J20 -> 157500 | L20: 0 | M20: =K20+L20 -> 157500 | N20: Sample rule; amend where business evidence supports a different split | O20: For review
